DEBUG:root:THIS IS THE PATH : /home/ottersome/project/dashTerm
INFO:oauth2client.client:Successfully retrieved access token
WARNING:googleapiclient.discovery_cache:file_cache is unavailable when using oauth2client >= 4.0.0
Traceback (most recent call last):
  File "/usr/lib/python3.6/site-packages/googleapiclient/discovery_cache/__init__.py", line 36, in autodetect
    from google.appengine.api import memcache
ModuleNotFoundError: No module named 'google'

During handling of the above exception, another exception occurred:

Traceback (most recent call last):
  File "/usr/lib/python3.6/site-packages/googleapiclient/discovery_cache/file_cache.py", line 33, in <module>
    from oauth2client.contrib.locked_file import LockedFile
ModuleNotFoundError: No module named 'oauth2client.contrib.locked_file'

During handling of the above exception, another exception occurred:

Traceback (most recent call last):
  File "/usr/lib/python3.6/site-packages/googleapiclient/discovery_cache/file_cache.py", line 37, in <module>
    from oauth2client.locked_file import LockedFile
ModuleNotFoundError: No module named 'oauth2client.locked_file'

During handling of the above exception, another exception occurred:

Traceback (most recent call last):
  File "/usr/lib/python3.6/site-packages/googleapiclient/discovery_cache/__init__.py", line 41, in autodetect
    from . import file_cache
  File "/usr/lib/python3.6/site-packages/googleapiclient/discovery_cache/file_cache.py", line 41, in <module>
    'file_cache is unavailable when using oauth2client >= 4.0.0')
ImportError: file_cache is unavailable when using oauth2client >= 4.0.0
INFO:googleapiclient.discovery:URL being requested: GET https://www.googleapis.com/discovery/v1/apis/oauth2/v2/rest
INFO:googleapiclient.discovery:URL being requested: GET https://www.googleapis.com/oauth2/v2/userinfo?alt=json
DEBUG:urllib3.connectionpool:Starting new HTTPS connection (1): accounts.spotify.com
DEBUG:urllib3.connectionpool:https://accounts.spotify.com:443 "POST /api/token HTTP/1.1" 400 71
